<?xml version="1.0" encoding="utf-8"?>
<robot name="mybot_v2">
  <material name="black">
    <color rgba="0.29804 0.29804 0.29804 1" />
  </material>
  <material name="silver">
    <color rgba="0.84706 0.84706 0.84706 1" />
  </material>
  <material name="white">
    <color rgba="1 1 1 1" />
  </material>
  <material name="red">
    <color rgba="1.0 0.0 0.0 1.0"/>
  </material>
  <link name="base">
    <visual>
      <origin rpy="0 0 0" xyz="0 0 0"/>
      <geometry>
        <box size="0.001 0.001 0.001"/>
      </geometry>
    </visual>
  </link>
  <joint name="floating_base" type="fixed">
    <origin rpy="0 0 0" xyz="0 0 0"/>
    <parent link="base"/>
    <child link="body"/>
  </joint>

  <link name="body">
    <inertial>
      <origin xyz="-0.06040900 -0.00003518 -0.07387929" rpy="0 0 0" />
      <mass value="3.87237343" />
      <inertia ixx="0.02571059" ixy="0.00000006" ixz="0.00004843" iyy="0.06723706" iyz="0.00000039" izz="0.07678240" />
    </inertial>
    <visual>
      <origin xyz="0 0 0" rpy="0 0 0" />
      <geometry>
        <mesh filename="package://deploy_cpp/robot/mybot_v2/meshes/body.STL" />
      </geometry>
      <material name="silver" />
    </visual>
    <collision>
      <origin xyz="-0.05 0 -0.09" rpy="0 0 0" />
      <geometry>
        <box size="0.30 0.2 0.16" />
      </geometry>
    </collision>
  </link>

<joint name="imu_joint" type="fixed">
    <parent link="body"/>
    <child link="imu_link"/>
    <origin rpy="0 0 0" xyz="-0.05 0 -0.16"/> 
  </joint>
  
  <link name="imu_link">
    <inertial>
      <mass value="0.001"/>
      <origin rpy="0 0 0" xyz="0 0 0"/>
      <inertia ixx="0.0001" ixy="0" ixz="0" iyy="0.0001" iyz="0" izz="0.0001"/>
    </inertial>
    <visual>
      <origin rpy="0 0 0" xyz="0 0 0"/>
      <geometry>
        <box size="0.01 0.01 0.01"/>
      </geometry>
      <material name="red"/>
    </visual>
    </link>

  <link name="FL_hip">
    <inertial>
      <origin xyz="0.06912954 0.00308032 -0.00003864" rpy="0 0 0" />
      <mass value="0.88715151" />
      <inertia ixx="0.00069961" ixy="-0.00005524" ixz="0.00000161" iyy="0.00185100" iyz="-0.00000029" izz="0.00156540" />
    </inertial>
    <visual>
      <origin xyz="0 0 0" rpy="0 0 0" />
      <geometry>
        <mesh filename="package://deploy_cpp/robot/mybot_v2/meshes/FL_hip.STL" />
      </geometry>
      <material name="white" />
    </visual>
    <collision>
      <origin xyz="0 0 0" rpy="1.5707963 0 0" />
      <geometry>
        <cylinder length="0.06" radius="0.04" />
      </geometry>
    </collision>
  </link>
  
  <joint name="FL_hip_joint" type="revolute">
    <origin xyz="0.0906 0.062 -0.071" rpy="0 0 0" />
    <parent link="body" />
    <child link="FL_hip" />
    <axis xyz="1 0 0" />
    <dynamics damping="0.0" friction="0.1"/>
    <limit effort="33.5" lower="-0.8" upper="0.8" velocity="28"/>
  </joint>

  <link name="FL_thigh">
    <inertial>
      <origin xyz="-0.00176951 0.05306396 -0.03995815" rpy="0 0 0" />
      <mass value="1.57937423" />
      <inertia ixx="0.00867755" ixy="6.478E-05" ixz="-0.00018618" iyy="0.00831722" iyz="0.00140967" izz="0.00215563" />
    </inertial>
    <visual>
      <origin xyz="0 0 0" rpy="0 0 0" />
      <geometry>
        <mesh filename="package://deploy_cpp/robot/mybot_v2/meshes/FL_thigh.STL" />
      </geometry>
      <material name="white" />
    </visual>
    <collision>
      <origin xyz="0 0.08 -0.1" rpy="0 0 0" />
      <geometry>
        <box size="0.04 0.04 0.2" />
      </geometry>
    </collision>
  </link>

  <joint name="FL_thigh_joint" type="revolute">
    <origin xyz="0.089 0.02895 0" rpy="0 0 0" />
    <parent link="FL_hip" />
    <child link="FL_thigh" />
    <axis xyz="0 1 0" />
    <dynamics damping="0.0" friction="0.1"/>
    <limit effort="33.5" lower="-1.04" upper="4.18" velocity="28"/>
  </joint>

  <link name="FL_calf">
    <inertial>
      <origin xyz="0.0023755 -2.9153E-05 -0.085563" rpy="0 0 0" />
      <mass value="0.34494" />
      <inertia ixx="0.00211121" ixy="3E-07" ixz="0.00039966" iyy="0.00219234" iyz="-1.92E-06" izz="0.00015881" />
    </inertial>
    <visual>
      <origin xyz="0 0 0" rpy="0 0 0" />
      <geometry>
        <mesh filename="package://deploy_cpp/robot/mybot_v2/meshes/FL_calf.STL" />
      </geometry>
      <material name="silver" />
    </visual>
    <collision>
      <origin xyz="0 0 -0.1" rpy="0 0 0" />
      <geometry>
        <box size="0.02 0.02 0.2" />
      </geometry>
    </collision>
  </link>

  <joint name="FL_calf_joint" type="revolute">
    <origin xyz="0 0.0753 -0.22" rpy="0 0 0" />
    <parent link="FL_thigh" />
    <child link="FL_calf" />
    <axis xyz="0 1 0" />
    <dynamics damping="0.0" friction="0.3"/>
    <limit effort="78.17" lower="-2.69" upper="-0.91" velocity="12.0"/>
  </joint>

  <link name="FL_foot">
    <inertial>
      <origin xyz="0 0 0" rpy="0 0 0" />
      <mass value="0.03351" />
      <inertia ixx="5.3617E-06" ixy="0" ixz="0" iyy="5.3617E-06" iyz="0" izz="5.3617E-06" />
    </inertial>
    <visual>
      <origin xyz="0 0 0" rpy="0 0 0" />
      <geometry>
        <mesh filename="package://deploy_cpp/robot/mybot_v2/meshes/FL_foot.STL" />
      </geometry>
      <material name="black" />
    </visual>
    <collision>
      <origin xyz="0 0 0" rpy="0 0 0" />
      <geometry>
        <sphere radius="0.02" />
      </geometry>
    </collision>
  </link>

  <joint name="FL_foot_joint" type="fixed">
    <origin xyz="0 -0.00025 -0.22336" rpy="0 0 0" />
    <parent link="FL_calf" />
    <child link="FL_foot" />
    <axis xyz="0 0 0" />
  </joint>

  <link name="FR_hip">
    <inertial>
      <origin xyz="0.06924677 -0.00308032 -0.00003847" rpy="0 0 0" />
      <mass value="0.88715151" />
      <inertia ixx="0.00069961" ixy="0.00005408" ixz="-0.00000026" iyy="0.00185513" iyz="0.00000029" izz="0.00156952" />
    </inertial>
    <visual>
      <origin xyz="0 0 0" rpy="0 0 0" />
      <geometry>
        <mesh filename="package://deploy_cpp/robot/mybot_v2/meshes/FR_hip.STL" />
      </geometry>
      <material name="white" />
    </visual>
    <collision>
      <origin xyz="0 0 0" rpy="1.5707963 0 0" />
      <geometry>
        <cylinder length="0.06" radius="0.04" />
      </geometry>
    </collision>
  </link>

  <joint name="FR_hip_joint" type="revolute">
    <origin xyz="0.0906 -0.062 -0.071" rpy="0 0 0" />
    <parent link="body" />
    <child link="FR_hip" />
    <axis xyz="1 0 0" />
    <dynamics damping="0.0" friction="0.1"/>
    <limit effort="33.5" lower="-0.8" upper="0.8" velocity="28"/>
  </joint>

  <link name="FR_thigh">
    <inertial>
      <origin xyz="-0.00184722 -0.05308638 -0.03995616" rpy="0 0 0" />
      <mass value="1.58133941" />
      <inertia ixx="0.00867822" ixy="-6.202E-05" ixz="-0.00018385" iyy="0.00831708" iyz="-0.00140961" izz="0.00215611" />
    </inertial>
    <visual>
      <origin xyz="0 0 0" rpy="0 0 0" />
      <geometry>
        <mesh filename="package://deploy_cpp/robot/mybot_v2/meshes/FR_thigh.STL" />
      </geometry>
      <material name="white" />
    </visual>
    <collision>
      <origin xyz="0 -0.08 -0.1" rpy="0 0 0" />
      <geometry>
        <box size="0.04 0.04 0.2" />
      </geometry>
    </collision>
  </link>

  <joint name="FR_thigh_joint" type="revolute">
    <origin xyz="0.089 -0.02895 0" rpy="0 0 0" />
    <parent link="FR_hip" />
    <child link="FR_thigh" />
    <axis xyz="0 1 0" />
    <dynamics damping="0.0" friction="0.1"/>
    <limit effort="33.5" lower="-1.04" upper="4.18" velocity="28"/>
  </joint>

  <link name="FR_calf">
    <inertial>
      <origin xyz="0.0023755 2.6551E-05 -0.085563" rpy="0 0 0" />
      <mass value="0.34494" />
      <inertia ixx="0.00211121" ixy="-2.8E-07" ixz="0.00039966" iyy="0.00219234" iyz="1.82E-06" izz="0.00015881" />
    </inertial>
    <visual>
      <origin xyz="0 0 0" rpy="0 0 0" />
      <geometry>
        <mesh filename="package://deploy_cpp/robot/mybot_v2/meshes/FR_calf.STL" />
      </geometry>
      <material name="silver" />
    </visual>
    <collision>
      <origin xyz="0 0 -0.1" rpy="0 0 0" />
      <geometry>
        <box size="0.02 0.02 0.2" />
      </geometry>
    </collision>
  </link>

  <joint name="FR_calf_joint" type="revolute">
    <origin xyz="0 -0.0753 -0.22" rpy="0 0 0" />
    <parent link="FR_thigh" />
    <child link="FR_calf" />
    <axis xyz="0 1 0" />
    <dynamics damping="0.0" friction="0.3"/>
    <limit effort="78.17" lower="-2.69" upper="-0.91" velocity="12.0"/>
  </joint>

  <link name="FR_foot">
    <inertial>
      <origin xyz="0 0 0" rpy="0 0 0" />
      <mass value="0.03351" />
      <inertia ixx="5.3617E-06" ixy="0" ixz="0" iyy="5.3617E-06" iyz="0" izz="5.3617E-06" />
    </inertial>
    <visual>
      <origin xyz="0 0 0" rpy="0 0 0" />
      <geometry>
        <mesh filename="package://deploy_cpp/robot/mybot_v2/meshes/FR_foot.STL" />
      </geometry>
      <material name="black" />
    </visual>
    <collision>
      <origin xyz="0 0 0" rpy="0 0 0" />
      <geometry>
        <sphere radius="0.02" />
      </geometry>
    </collision>
  </link>

  <joint name="FR_foot_joint" type="fixed">
    <origin xyz="0 0.00025 -0.22336" rpy="0 0 0" />
    <parent link="FR_calf" />
    <child link="FR_foot" />
    <axis xyz="0 0 0" />
  </joint>

  <link name="RL_hip">
    <inertial>
      <origin xyz="-0.06912960 0.00308032 0.00003847" rpy="0 0 0" />
      <mass value="0.88715151" />
      <inertia ixx="0.00069961" ixy="0.00005524" ixz="0.00000161" iyy="0.00185101" iyz="0.00000029" izz="0.00156541" />
    </inertial>
    <visual>
      <origin xyz="0 0 0" rpy="0 0 0" />
      <geometry>
        <mesh filename="package://deploy_cpp/robot/mybot_v2/meshes/RL_hip.STL" />
      </geometry>
      <material name="white" />
    </visual>
    <collision>
      <origin xyz="0 0 0" rpy="1.5707963 0 0" />
      <geometry>
        <cylinder length="0.06" radius="0.04" />
      </geometry>
    </collision>
  </link>

  <joint name="RL_hip_joint" type="revolute">
    <origin xyz="-0.2106 0.062 -0.071" rpy="0 0 0" />
    <parent link="body" />
    <child link="RL_hip" />
    <axis xyz="1 0 0" />
    <dynamics damping="0.0" friction="0.1"/>
    <limit effort="33.5" lower="-0.8" upper="0.8" velocity="28"/>
  </joint>

  <link name="RL_thigh">
    <inertial>
      <origin xyz="-0.00271376 0.05342776 -0.03973152" rpy="0 0 0" />
      <mass value="1.593154" />
      <inertia ixx="0.00874288" ixy="9.667E-05" ixz="-0.00020428" iyy="0.00841103" iyz="0.00139054" izz="0.00223462" />
    </inertial>
    <visual>
      <origin xyz="0 0 0" rpy="0 0 0" />
      <geometry>
        <mesh filename="package://deploy_cpp/robot/mybot_v2/meshes/RL_thigh.STL" />
      </geometry>
      <material name="white" />
    </visual>
    <collision>
      <origin xyz="0 0.08 -0.1" rpy="0 0 0" />
      <geometry>
        <box size="0.04 0.04 0.2" />
      </geometry>
    </collision>
  </link>

  <joint name="RL_thigh_joint" type="revolute">
    <origin xyz="-0.089 0.02895 0" rpy="0 0 0" />
    <parent link="RL_hip" />
    <child link="RL_thigh" />
    <axis xyz="0 1 0" />
    <dynamics damping="0.0" friction="0.1"/>
    <limit effort="33.5" lower="-1.04" upper="4.18" velocity="28"/>
  </joint>

  <link name="RL_calf">
    <inertial>
      <origin xyz="0.0023755 -4.7806E-05 -0.085563" rpy="0 0 0" />
      <mass value="0.34494" />
      <inertia ixx="0.00211121" ixy="2.2E-07" ixz="0.00039966" iyy="0.00219234" iyz="-1.23E-06" izz="0.00015881" />
    </inertial>
    <visual>
      <origin xyz="0 0 0" rpy="0 0 0" />
      <geometry>
        <mesh filename="package://deploy_cpp/robot/mybot_v2/meshes/RL_calf.STL" />
      </geometry>
      <material name="silver" />
    </visual>
    <collision>
      <origin xyz="0 0 -0.1" rpy="0 0 0" />
      <geometry>
        <box size="0.02 0.02 0.2" />
      </geometry>
    </collision>
  </link>

  <joint name="RL_calf_joint" type="revolute">
    <origin xyz="0 0.0753 -0.22" rpy="0 0 0" />
    <parent link="RL_thigh" />
    <child link="RL_calf" />
    <axis xyz="0 1 0" />
    <dynamics damping="0.0" friction="0.3"/>
    <limit effort="78.17" lower="-2.69" upper="-0.91" velocity="12.0"/>
  </joint>

  <link name="RL_foot">
    <inertial>
      <origin xyz="0 0 0" rpy="0 0 0" />
      <mass value="0.03351" />
      <inertia ixx="5.3617E-06" ixy="0" ixz="0" iyy="5.3617E-06" iyz="0" izz="5.3617E-06" />
    </inertial>
    <visual>
      <origin xyz="0 0 0" rpy="0 0 0" />
      <geometry>
        <mesh filename="package://deploy_cpp/robot/mybot_v2/meshes/RL_foot.STL" />
      </geometry>
      <material name="black" />
    </visual>
    <collision>
      <origin xyz="0 0 0" rpy="0 0 0" />
      <geometry>
        <sphere radius="0.02" />
      </geometry>
    </collision>
  </link>

  <joint name="RL_foot_joint" type="fixed">
    <origin xyz="0 -0.00025 -0.22336" rpy="0 0 0" />
    <parent link="RL_calf" />
    <child link="RL_foot" />
    <axis xyz="0 0 0" />
  </joint>

  <link name="RR_hip">
    <inertial>
      <origin xyz="-0.06924676 -0.00308032 0.00003847" rpy="0 0 0" />
      <mass value="0.88715151" />
      <inertia ixx="0.00069961" ixy="-0.00005408" ixz="-0.00000026" iyy="0.00185513" iyz="-0.00000029" izz="0.00156952" />
    </inertial>
    <visual>
      <origin xyz="0 0 0" rpy="0 0 0" />
      <geometry>
        <mesh filename="package://deploy_cpp/robot/mybot_v2/meshes/RR_hip.STL" />
      </geometry>
      <material name="silver" />
    </visual>
    <collision>
      <origin xyz="0 0 0" rpy="1.5707963 0 0" />
      <geometry>
        <cylinder length="0.06" radius="0.04" />
      </geometry>
    </collision>
  </link>

  <joint name="RR_hip_joint" type="revolute">
    <origin xyz="-0.2106 -0.062 -0.071" rpy="0 0 0" />
    <parent link="body" />
    <child link="RR_hip" />
    <axis xyz="1 0 0" />
    <dynamics damping="0.0" friction="0.1"/>
    <limit effort="33.5" lower="-0.8" upper="0.8" velocity="28"/>
  </joint>

  <link name="RR_thigh">
    <inertial>
      <origin xyz="-0.00297935 -0.05327553 -0.03814011" rpy="0 0 0" />
      <mass value="1.58306405" />
      <inertia ixx="0.00816821" ixy="-0.00010062" ixz="-0.00025438" iyy="0.00785378" iyz="-0.00133132" izz="0.00221841" />
    </inertial>
    <visual>
      <origin xyz="0 0 0" rpy="0 0 0" />
      <geometry>
        <mesh filename="package://deploy_cpp/robot/mybot_v2/meshes/RR_thigh.STL" />
      </geometry>
      <material name="white" />
    </visual>
    <collision>
      <origin xyz="0 -0.08 -0.1" rpy="0 0 0" />
      <geometry>
        <box size="0.04 0.04 0.2" />
      </geometry>
    </collision>
  </link>

  <joint name="RR_thigh_joint" type="revolute">
    <origin xyz="-0.088999695625364 -0.0289499999999917 0" rpy="0 0 0" />
    <parent link="RR_hip" />
    <child link="RR_thigh" />
    <axis xyz="0 1 0" />
    <dynamics damping="0.0" friction="0.1"/>
    <limit effort="33.5" lower="-1.04" upper="4.18" velocity="28"/>
  </joint>

  <link name="RR_calf">
    <inertial>
      <origin xyz="0.0031074 -3.1371E-05 -0.084827" rpy="0 0 0" />
      <mass value="0.35539" />
      <inertia ixx="0.00207591" ixy="-3E-07" ixz="0.0003696" iyy="0.00214155" iyz="3.47E-06" izz="0.00016557" />
    </inertial>
    <visual>
      <origin xyz="0 0 0" rpy="0 0 0" />
      <geometry>
        <mesh filename="package://deploy_cpp/robot/mybot_v2/meshes/RR_calf.STL" />
      </geometry>
      <material name="silver" />
    </visual>
    <collision>
      <origin xyz="0 0 -0.1" rpy="0 0 0" />
      <geometry>
        <box size="0.02 0.02 0.2" />
      </geometry>
    </collision>
  </link>

  <joint name="RR_calf_joint" type="revolute">
    <origin xyz="0 -0.0753 -0.22" rpy="0 0 0" />
    <parent link="RR_thigh" />
    <child link="RR_calf" />
    <axis xyz="0 1 0" />
    <dynamics damping="0.0" friction="0.3"/>
    <limit effort="78.17" lower="-2.69" upper="-0.91" velocity="12.0"/>
  </joint>

  <link name="RR_foot">
    <inertial>
      <origin xyz="0 0 0" rpy="0 0 0" />
      <mass value="0.03351" />
      <inertia ixx="5.3617E-06" ixy="0" ixz="0" iyy="5.3617E-06" iyz="0" izz="5.3617E-06" />
    </inertial>
    <visual>
      <origin xyz="0 0 0" rpy="0 0 0" />
      <geometry>
        <mesh filename="package://deploy_cpp/robot/mybot_v2/meshes/RR_foot.STL" />
      </geometry>
      <material name="black" />
    </visual>
    <collision>
      <origin xyz="0 0 0" rpy="0 0 0" />
      <geometry>
        <sphere radius="0.02" />
      </geometry>
    </collision>
  </link>

  <joint name="RR_foot_joint" type="fixed">
    <origin xyz="0 0.00025 -0.22336" rpy="0 0 0" />
    <parent link="RR_calf" />
    <child link="RR_foot" />
    <axis xyz="0 0 0" />
  </joint>
</robot>
