<?xml version='1.0' encoding='utf-8'?>
<mujoco model="mybot_v3">
    <compiler angle="radian" meshdir="../meshes/" autolimits="true" />
    <size njmax="500" nconmax="100" />
    <option gravity="0 0 -9.806" iterations="50" solver="Newton" timestep="0.005" />

    <default>
        <default class="dog_v2">
            <geom contype="1" conaffinity="1" friction="0.6 0.3 0.3" rgba="0.5 0.6 0.7 1" margin="0.001" group="0" />
            <joint armature="0.01" damping="2" frictionloss="0.2" />
            <motor ctrlrange="-33.5 33.5" ctrllimited="true" />
            
            <default class="abduction">
                <joint damping="1" />
            </default>
            <default class="thigh">
                <joint damping="2" />
            </default>
            <default class="calf">
                <joint damping="2" armature="0.0544" />
                <motor gear="2.3333" />
            </default>
        </default>

        <light castshadow="false" diffuse="1 1 1" />
        <camera fovy="60" />
    </default>

    <asset>
        <mesh name="body" file="body.STL" />
        <mesh name="FL_hip" file="FL_hip.STL" />
        <mesh name="FL_thigh" file="FL_thigh.STL" />
        <mesh name="FL_calf" file="FL_calf.STL" />
        <mesh name="FL_foot" file="FL_foot.STL" />
        <mesh name="FR_hip" file="FR_hip.STL" />
        <mesh name="FR_thigh" file="FR_thigh.STL" />
        <mesh name="FR_calf" file="FR_calf.STL" />
        <mesh name="FR_foot" file="FR_foot.STL" />
        <mesh name="RL_hip" file="RL_hip.STL" />
        <mesh name="RL_thigh" file="RL_thigh.STL" />
        <mesh name="RL_calf" file="RL_calf.STL" />
        <mesh name="RL_foot" file="RL_foot.STL" />
        <mesh name="RR_hip" file="RR_hip.STL" />
        <mesh name="RR_thigh" file="RR_thigh.STL" />
        <mesh name="RR_calf" file="RR_calf.STL" />
        <mesh name="RR_foot" file="RR_foot.STL" />

        <texture type="skybox" builtin="gradient" rgb1="1.0 1.0 1.0" rgb2="1.0 1.0 1.0" width="512" height="512" />
        <texture name="plane" type="2d" builtin="flat" rgb1="1 1 1" rgb2="1 1 1" width="512" height="512" mark="cross" markrgb="0 0 0" />
        <material name="plane" reflectance="0.0" texture="plane" texrepeat="3 3" texuniform="true" />
    </asset>

    <visual>
        <rgba com="0.502 1.0 0 0.5" contactforce="0.98 0.4 0.4 0.7" contactpoint="1.0 1.0 0.6 0.4" />
        <scale com="0.2" forcewidth="0.035" contactwidth="0.10" contactheight="0.04" />
    </visual>

    <worldbody>
        <light directional="true" diffuse=".8 .8 .8" pos="0 0 10" dir="0 0 -10" />
        <camera name="track" mode="trackcom" pos="0 -1.3 1.6" xyaxes="1 0 0 0 0.707 0.707" />
        <geom name="floor" type="plane" conaffinity="1" condim="3" contype="1" rgba="0.5 0.9 0.9 0.1" material="plane" pos="0 0 0" size="0 0 1" />

        <!-- 10 steps, 0.07 m rise each, placed in +X direction -->
        <geom name="step_0" type="box" pos="0.5 0.0 0.035" size="0.125 0.9 0.035" rgba="0.6 0.6 0.6 1" />
        <geom name="step_1" type="box" pos="0.75 0.0 0.105" size="0.125 0.9 0.035" rgba="0.6 0.6 0.6 1" />
        <geom name="step_2" type="box" pos="1.0 0.0 0.175" size="0.125 0.9 0.035" rgba="0.6 0.6 0.6 1" />
        <geom name="step_3" type="box" pos="1.25 0.0 0.245" size="0.125 0.9 0.035" rgba="0.6 0.6 0.6 1" />
        <geom name="step_4" type="box" pos="1.5 0.0 0.315" size="0.125 0.9 0.035" rgba="0.6 0.6 0.6 1" />
        <geom name="step_5" type="box" pos="1.75 0.0 0.385" size="0.125 0.9 0.035" rgba="0.6 0.6 0.6 1" />
        <geom name="step_6" type="box" pos="2.0 0.0 0.455" size="0.125 0.9 0.035" rgba="0.6 0.6 0.6 1" />
        <geom name="step_7" type="box" pos="2.25 0.0 0.525" size="0.125 0.9 0.035" rgba="0.6 0.6 0.6 1" />
        <geom name="step_8" type="box" pos="2.5 0.0 0.595" size="0.125 0.9 0.035" rgba="0.6 0.6 0.6 1" />
        <geom name="step_9" type="box" pos="2.75 0.0 0.665" size="0.125 0.9 0.035" rgba="0.6 0.6 0.6 1" />

        <!-- 10 steps, 0.10 m rise each, shifted +Y by 0.10 -->
        <geom name="step10_0" type="box" pos="2.5 2.0 0.05" size="0.125 0.9 0.05" rgba="0.6 0.6 0.6 1" />
        <geom name="step10_1" type="box" pos="2.75 2.0 0.15" size="0.125 0.9 0.05" rgba="0.6 0.6 0.6 1" />
        <geom name="step10_2" type="box" pos="3.0 2.0 0.25" size="0.125 0.9 0.05" rgba="0.6 0.6 0.6 1" />
        <geom name="step10_3" type="box" pos="3.25 2.0 0.35" size="0.125 0.9 0.05" rgba="0.6 0.6 0.6 1" />
        <geom name="step10_4" type="box" pos="3.5 2.0 0.45" size="0.125 0.9 0.05" rgba="0.6 0.6 0.6 1" />
        <geom name="step10_5" type="box" pos="3.75 2.0 0.55" size="0.125 0.9 0.05" rgba="0.6 0.6 0.6 1" />
        <geom name="step10_6" type="box" pos="4.0 2.0 0.65" size="0.125 0.9 0.05" rgba="0.6 0.6 0.6 1" />
        <geom name="step10_7" type="box" pos="4.25 2.0 0.75" size="0.125 0.9 0.05" rgba="0.6 0.6 0.6 1" />
        <geom name="step10_8" type="box" pos="4.5 2.0 0.85" size="0.125 0.9 0.05" rgba="0.6 0.6 0.6 1" />
        <geom name="step10_9" type="box" pos="4.75 2.0 0.95" size="0.125 0.9 0.05" rgba="0.6 0.6 0.6 1" />
        <!-- 20 deg ramp to the right of the steps (positive Y), 0.2 m gap from steps -->
        <geom name="ramp_0" type="box" pos="4.075 1.7 0.10" size="1.0 0.6 0.10" euler="0 -0.349066 0" rgba="0.55 0.55 0.55 1" />

        <body name="body" pos="0 0 0.35" childclass="dog_v2">
            <inertial pos="0.00000000 0.00000000 0.00000000" mass="3.87237343" fullinertia="0.02571059 0.06723291 0.07677825 0.00000003 0.00005548 0.00000039" />
            <joint type="free" />
            <geom type="mesh" contype="0" conaffinity="0" group="1" rgba="0.847 0.847 0.847 1" mesh="body" />
            <geom size="0.15 0.1 0.08" pos="-0.0 0 -0.0" type="box" rgba="0.913 0.913 0.847 0" />
            <site name="imu" pos="0 0 0" />

            <body name="FL_hip" pos="0.15078 0.062035 0.0028793">
                <inertial pos="0.06912954 0.00308032 -0.00003864" mass="0.88715151" fullinertia="0.00069961 0.00185100 0.00156540 -0.00005524 0.00000161 -0.00000029" />
                <joint class="abduction" name="FL_hip_joint" pos="0 0 0" axis="1 0 0" range="-0.8 0.8" />
                <geom type="mesh" contype="0" conaffinity="0" group="1" rgba="1 1 1 1" mesh="FL_hip" />
                <geom size="0.04 0.03" euler="1.5707963 0 0" type="cylinder" rgba="0.913 0.913 0.847 0" />

                <body name="FL_thigh" pos="0.0889996956253644 0.0289500000000045 0">
                    <inertial pos="-0.00157835 0.05108903 -0.03349728" mass="1.44059854" fullinertia="0.00712300 0.00681289 0.00198498 0.00006001 -0.00006848 0.00118491" />
                    <joint class="thigh" name="FL_thigh_joint" pos="0 0 0" axis="0 1 0" range="-1.04 4.18" />
                    <geom type="mesh" contype="0" conaffinity="0" group="1" rgba="1 1 1 1" mesh="FL_thigh" />
                    <geom size="0.02 0.02 0.1" pos="0 0.08 -0.1" type="box" rgba="0.913 0.913 0.847 0" />
                    
                    <body name="FL_calf" pos="0 0.075299999999995 -0.220000271728273">
                        <inertial pos="0.00128763 0.00019208 -0.06746137" mass="0.23708419" fullinertia="0.00201781 0.00206401 0.00012004 -0.00000038 0.00025632 0.00000347" />
                        <joint class="calf" name="FL_calf_joint" pos="0 0 0" axis="0 1 0" range="-2.69 -0.91" />
                        <geom type="mesh" contype="0" conaffinity="0" group="1" rgba="0.847 0.847 0.847 1" mesh="FL_calf" />
                        <geom size="0.01 0.01 0.1" pos="0 0 -0.1" type="box" rgba="0 0 0 0" />
                        
                        <body name="FL_foot" pos="0 0.000400000000007244 -0.226044482407549">
                            <inertial pos="0.00000000 0.00000000 0.00000000" mass="0.03900000" fullinertia="0.00000624 0.00000624 0.00000624 0.00000000 0.00000000 0.00000000" />
                            <geom type="mesh" contype="0" conaffinity="0" group="1" rgba="0.298 0.298 0.298 1" mesh="FL_foot" />
                            <geom size="0.02" type="sphere" rgba="0 0 0 1" />
                        </body>
                    </body>
                </body>
            </body>

            <body name="FR_hip" pos="0.15078 -0.061965 0.0028793">
                <inertial pos="0.06924677 -0.00308032 -0.00003847" mass="0.88715151" fullinertia="0.00069961 0.00185513 0.00156952 0.00005408 -0.00000026 0.00000029" />
                <joint class="abduction" name="FR_hip_joint" pos="0 0 0" axis="1 0 0" range="-0.8 0.8" />
                <geom type="mesh" contype="0" conaffinity="0" group="1" rgba="1 1 1 1" mesh="FR_hip" />
                <geom size="0.04 0.03" euler="1.5707963 0 0" type="cylinder" rgba="0.913 0.913 0.847 0" />

                <body name="FR_thigh" pos="0.0889996956253649 -0.0289500000000027 0">
                    <inertial pos="-0.00165058 -0.05108904 -0.03349728" mass="1.44059854" fullinertia="0.00712300 0.00681255 0.00198464 -0.00005712 -0.00006685 -0.00118491" />
                    <joint class="thigh" name="FR_thigh_joint" pos="0 0 0" axis="0 1 0" range="-1.04 4.18" />
                    <geom type="mesh" contype="0" conaffinity="0" group="1" rgba="1 1 1 1" mesh="FR_thigh" />
                    <geom size="0.02 0.02 0.1" pos="0 -0.08 -0.1" type="box" rgba="0.913 0.913 0.847 0" />
                    
                    <body name="FR_calf" pos="0 -0.0752999999999995 -0.220000271728275">
                        <inertial pos="0.00128778 0.00059175 -0.06722727" mass="0.23765586" fullinertia="0.00208296 0.00206862 0.00018061 0.00000010 0.00025619 -0.00002062" />
                        <joint class="calf" name="FR_calf_joint" pos="0 0 0" axis="0 1 0" range="-2.69 -0.91" />
                        <geom type="mesh" contype="0" conaffinity="0" group="1" rgba="0.847 0.847 0.847 1" mesh="FR_calf" />
                        <geom size="0.01 0.01 0.1" pos="0 0 -0.1" type="box" rgba="0 0 0 0" />
                        
                        <body name="FR_foot" pos="0 -0.000399999999994072 -0.226044482407548">
                            <inertial pos="0.00000000 0.00000000 0.00000000" mass="0.03900000" fullinertia="0.00000624 0.00000624 0.00000624 0.00000000 0.00000000 0.00000000" />
                            <geom type="mesh" contype="0" conaffinity="0" group="1" rgba="0.298 0.298 0.298 1" mesh="FR_foot" />
                            <geom size="0.02" type="sphere" rgba="0 0 0 1" />
                        </body>
                    </body>
                </body>
            </body>

            <body name="RL_hip" pos="-0.15042 0.062035 0.0028793">
                <inertial pos="-0.06912961 0.00308032 0.00003847" mass="0.88715151" fullinertia="0.00069961 0.00185101 0.00156540 0.00005524 0.00000161 0.00000029" />
                <joint class="abduction" name="RL_hip_joint" pos="0 0 0" axis="1 0 0" range="-0.8 0.8" />
                <geom type="mesh" contype="0" conaffinity="0" group="1" rgba="1 1 1 1" mesh="RL_hip" />
                <geom size="0.04 0.03" euler="1.5707963 0 0" type="cylinder" rgba="0.913 0.913 0.847 0" />

                <body name="RL_thigh" pos="-0.0889996956253643 0.0289499874999981 0">
                    <inertial pos="-0.00160464 0.05142477 -0.03321690" mass="1.45185979" fullinertia="0.00716742 0.00683898 0.00201350 0.00006033 -0.00006711 0.00116896" />
                    <joint class="thigh" name="RL_thigh_joint" pos="0 0 0" axis="0 1 0" range="-1.04 4.18" />
                    <geom type="mesh" contype="0" conaffinity="0" group="1" rgba="1 1 1 1" mesh="RL_thigh" />
                    <geom size="0.02 0.02 0.1" pos="0 0.08 -0.1" type="box" rgba="0.913 0.913 0.847 0" />
                    
                    <body name="RL_calf" pos="0 0.0752999999999953 -0.220000271728273">
                        <inertial pos="0.00125720 0.00001358 -0.06699953" mass="0.23880158" fullinertia="0.00202425 0.00207095 0.00011991 0.00000000 0.00025653 -0.00000027" />
                        <joint class="calf" name="RL_calf_joint" pos="0 0 0" axis="0 1 0" range="-2.69 -0.91" />
                        <geom type="mesh" contype="0" conaffinity="0" group="1" rgba="0.847 0.847 0.847 1" mesh="RL_calf" />
                        <geom size="0.01 0.01 0.1" pos="0 0 -0.1" type="box" rgba="0 0 0 0" />
                        
                        <body name="RL_foot" pos="0 0 -0.226044482410381">
                            <inertial pos="0.00000000 0.00000000 0.00000000" mass="0.03900000" fullinertia="0.00000624 0.00000624 0.00000624 0.00000000 0.00000000 0.00000000" />
                            <geom type="mesh" contype="0" conaffinity="0" group="1" rgba="0.298 0.298 0.298 1" mesh="RL_foot" />
                            <geom size="0.02" type="sphere" rgba="0 0 0 1" />
                        </body>
                    </body>
                </body>
            </body>

            <body name="RR_hip" pos="-0.150422440000001 -0.0619648146458117 0.00287929128020871">
                <inertial pos="-0.06924676 -0.00308032 0.00003847" mass="0.88715151" fullinertia="0.00069961 0.00185513 0.00156952 -0.00005408 -0.00000026 -0.00000029" />
                <joint class="abduction" name="RR_hip_joint" pos="0 0 0" axis="1 0 0" range="-0.8 0.8" />
                <geom type="mesh" contype="0" conaffinity="0" group="1" rgba="0.847 0.847 0.847 1" mesh="RR_hip" />
                <geom size="0.04 0.03" euler="1.5707963 0 0" type="cylinder" rgba="0.913 0.913 0.847 0" />

                <body name="RR_thigh" pos="-0.0889996956253639 -0.0289499875000004 0">
                    <inertial pos="-0.00167539 -0.05090610 -0.02942817" mass="1.42118841" fullinertia="0.00608478 0.00578599 0.00198060 -0.00005774 -0.00007671 -0.00103286" />
                    <joint class="thigh" name="RR_thigh_joint" pos="0 0 0" axis="0 1 0" range="-1.04 4.18" />
                    <geom type="mesh" contype="0" conaffinity="0" group="1" rgba="1 1 1 1" mesh="RR_thigh" />
                    <geom size="0.02 0.02 0.1" pos="0 -0.08 -0.1" type="box" rgba="0.913 0.913 0.847 0" />
                    
                    <body name="RR_calf" pos="0 -0.0752999999999974 -0.220000271728273">
                        <inertial pos="0.00105039 -0.00009676 -0.06329053" mass="0.25719862" fullinertia="0.00207090 0.00210651 0.00013106 -0.00000003 0.00026042 0.00000158" />
                        <joint class="calf" name="RR_calf_joint" pos="0 0 0" axis="0 1 0" range="-2.69 -0.91" />
                        <geom type="mesh" contype="0" conaffinity="0" group="1" rgba="0.847 0.847 0.847 1" mesh="RR_calf" />
                        <geom size="0.01 0.01 0.1" pos="0 0 -0.1" type="box" rgba="0 0 0 0" />
                        
                        <body name="RR_foot" pos="0 0 -0.226044482410382">
                            <inertial pos="0.00000000 0.00000000 0.00000000" mass="0.03900000" fullinertia="0.00000624 0.00000624 0.00000624 0.00000000 0.00000000 0.00000000" />
                            <geom type="mesh" contype="0" conaffinity="0" group="1" rgba="0.298 0.298 0.298 1" mesh="RR_foot" />
                            <geom size="0.02" type="sphere" rgba="0 0 0 1" />
                        </body>
                    </body>
                </body>
            </body>
        </body>
    </worldbody>

    <actuator>       
        <motor class="abduction" name="FL_hip" gear="1" joint="FL_hip_joint" />
        <motor class="thigh" name="FL_thigh" gear="1" joint="FL_thigh_joint" />
        <motor class="calf" name="FL_calf" joint="FL_calf_joint" />
        <motor class="abduction" name="FR_hip" gear="1" joint="FR_hip_joint" />
        <motor class="thigh" name="FR_thigh" gear="1" joint="FR_thigh_joint" />
        <motor class="calf" name="FR_calf" joint="FR_calf_joint" />
        <motor class="abduction" name="RL_hip" gear="1" joint="RL_hip_joint" />
        <motor class="thigh" name="RL_thigh" gear="1" joint="RL_thigh_joint" />
        <motor class="calf" name="RL_calf" joint="RL_calf_joint" />
        <motor class="abduction" name="RR_hip" gear="1" joint="RR_hip_joint" />
        <motor class="thigh" name="RR_thigh" gear="1" joint="RR_thigh_joint" />
        <motor class="calf" name="RR_calf" joint="RR_calf_joint" />
    </actuator>

    <sensor>
        <jointpos name="FL_hip_pos" joint="FL_hip_joint" />
        <jointpos name="FL_thigh_pos" joint="FL_thigh_joint" />
        <jointpos name="FL_calf_pos" joint="FL_calf_joint" />
        <jointpos name="FR_hip_pos" joint="FR_hip_joint" />
        <jointpos name="FR_thigh_pos" joint="FR_thigh_joint" />
        <jointpos name="FR_calf_pos" joint="FR_calf_joint" />
        <jointpos name="RL_hip_pos" joint="RL_hip_joint" />
        <jointpos name="RL_thigh_pos" joint="RL_thigh_joint" />
        <jointpos name="RL_calf_pos" joint="RL_calf_joint" />
        <jointpos name="RR_hip_pos" joint="RR_hip_joint" />
        <jointpos name="RR_thigh_pos" joint="RR_thigh_joint" />
        <jointpos name="RR_calf_pos" joint="RR_calf_joint" />

        <jointvel name="FL_hip_vel" joint="FL_hip_joint" />
        <jointvel name="FL_thigh_vel" joint="FL_thigh_joint" />
        <jointvel name="FL_calf_vel" joint="FL_calf_joint" />
        <jointvel name="FR_hip_vel" joint="FR_hip_joint" />
        <jointvel name="FR_thigh_vel" joint="FR_thigh_joint" />
        <jointvel name="FR_calf_vel" joint="FR_calf_joint" />
        <jointvel name="RL_hip_vel" joint="RL_hip_joint" />
        <jointvel name="RL_thigh_vel" joint="RL_thigh_joint" />
        <jointvel name="RL_calf_vel" joint="RL_calf_joint" />
        <jointvel name="RR_hip_vel" joint="RR_hip_joint" />
        <jointvel name="RR_thigh_vel" joint="RR_thigh_joint" />
        <jointvel name="RR_calf_vel" joint="RR_calf_joint" />

        <accelerometer name="Body_Acc" site="imu" />
        <gyro name="Body_Gyro" site="imu" />
        <framepos name="Body_Pos" objtype="site" objname="imu" />
        <framequat name="Body_Quat" objtype="site" objname="imu" />
    </sensor>
</mujoco>