<mujoco model="mybot_description">
    <compiler angle="radian" meshdir="../meshes" />
    <size njmax="500" nconmax="100" />
    <option gravity='0 0 -9.806' iterations='50' solver='Newton' timestep='0.002'/>

    <default>
        <geom contype="1" conaffinity="1" friction="0.6 0.3 0.3" rgba="0.5 0.6 0.7 1" margin="0.001" group="0"/>
        <light castshadow="false" diffuse="1 1 1"/>
        <motor ctrlrange="-33.5 33.5" ctrllimited="true"/>
        <camera fovy="60"/>
        <joint damping="0.6" armature="0.01" frictionloss="0.2" />
    </default>

    <asset>
        <mesh name="body" file="body.obj" />
        <mesh name="FL_hip" file="FL_hip.obj" />
        <mesh name="FL_thigh" file="FL_thigh.obj" />
        <mesh name="FL_calf" file="FL_calf.obj" />
        <mesh name="FL_foot" file="FL_foot.obj" />
        <mesh name="FR_hip" file="FR_hip.obj" />
        <mesh name="FR_thigh" file="FR_thigh.obj" />
        <mesh name="FR_calf" file="FR_calf.obj" />
        <mesh name="FR_foot" file="FR_foot.obj" />
        <mesh name="RL_hip" file="RL_hip.obj" />
        <mesh name="RL_thigh" file="RL_thigh.obj" />
        <mesh name="RL_calf" file="RL_calf.obj" />
        <mesh name="RL_foot" file="RL_foot.obj" />
        <mesh name="RR_hip" file="RR_hip.obj" />
        <mesh name="RR_thigh" file="RR_thigh.obj" />
        <mesh name="RR_calf" file="RR_calf.obj" />
        <mesh name="RR_foot" file="RR_foot.obj" />
    </asset>

    <asset>
        <texture type="skybox" builtin="gradient" rgb1="1.0 1.0 1.0" rgb2="1.0 1.0 1.0" width="512" height="512"/>
        <texture name="plane" type="2d" builtin="flat" rgb1="1 1 1" rgb2="1 1 1" width="512" height="512" mark="cross" markrgb="0 0 0"/>
        <material name="plane" reflectance="0.0" texture="plane" texrepeat="3 3" texuniform="true"/>
    </asset>

    <visual>
        <rgba com="0.502 1.0 0 0.5" contactforce="0.98 0.4 0.4 0.7" contactpoint="1.0 1.0 0.6 0.4"/>
        <scale com="0.2" forcewidth="0.035" contactwidth="0.10" contactheight="0.04"/>
    </visual>

    <worldbody>
        <light directional="true" diffuse=".8 .8 .8" pos="0 0 10" dir="0 0 -10"/>
        <camera name="track" mode="trackcom" pos="0 -1.3 1.6" xyaxes="1 0 0 0 0.707 0.707"/>
        <geom name='floor' type='plane' conaffinity='1' condim='3' contype='1' rgba="0.5 0.9 0.9 0.1" material='plane' pos='0 0 0' size='0 0 1'/>

        <body name="base" pos="0 0 0.445">
            <inertial pos="-0.075044 0.0013153 0.023062" quat="0.5 0.5 0.5 0.5" mass="5.3036" diaginertia="0.017259 0.017164 0.012634" />
            <joint type="free" />
            <geom type="mesh" contype="0" conaffinity="0" group="1" rgba="0.67 0.69 0.77 1" mesh="body" />
            <geom size="0.15 0.05 0.06" type="box" rgba="0.67 0.69 0.77 1" />
            <site name="imu" pos="0 0 0"/>
            <body name="FR_hip" pos="0.0946 -0.062 -0.071">
                <inertial pos="0.050324 -0.0023835 -1.926E-05" quat="0.5 0.5 -0.5 0.5" mass="0.64533" diaginertia="0.00081299 0.00051628 0.00043556" />
                <joint name="FR_hip_joint" pos="0 0 0" axis="1 0 0" limited="true" range="-0.48 0.48" />
                <geom type="mesh" contype="0" conaffinity="0" group="1" rgba="1 1 1 1" mesh="FR_hip" />
                <geom size="0.046 0.02" pos="0 -0.03 0" quat="0.707107 0.707107 0 0" type="cylinder" rgba="1 1 1 0" />

                <body name="FR_thigh" pos="0.085 -0.03295 0">
                    <inertial pos="0.0003687 -0.05094 -0.044849" quat="0.999 0 -0.038 0" mass="1.107" diaginertia="0.0030336 0.0026249 0.00046586" />
                    <joint name="FR_thigh_joint" pos="0 0 0" axis="0 1 0" limited="true" range="-1.44 1.44" />
                    <geom type="mesh" contype="0" conaffinity="0" group="1" rgba="1 1 1 1" mesh="FR_thigh" />
                    <geom size="0.11 0.012 0.017" pos="0 0 -0.11" quat="0.707107 0 0.707107 0" type="box" rgba="1 1 1 0" />
                    
                    <body name="FR_calf" pos="0 -0.0705 -0.22">
                        <inertial pos="0.01731 3.8634E-05 -0.100139" quat="0.762 0.01 0.018 0.647" mass="0.29248" diaginertia="0.0009493 0.0009031 0.00006325" />
                        <joint name="FR_calf_joint" pos="0 0 0" axis="0 1 0" limited="true" range="-2.7 -0.6" />
                        <geom type="mesh" contype="0" conaffinity="0" group="1" rgba="0 0 0 1" mesh="FR_calf" />
                        <geom size="0.1 0.008 0.008" pos="0 0 -0.1" quat="0.707107 0 0.707107 0" type="box" rgba="0 0 0 0" />
                        
                        <body name="FR_foot" pos="0.0015191 0.00025002 -0.22467">
                            <inertial pos="0 0 0" mass="0.0335" diaginertia="5.36e-6 5.36e-6 5.36e-6"/>
                            <geom type="mesh" contype="0" conaffinity="0" group="1" rgba="0 0 0 1" mesh="FR_foot" />
                            <geom size="0.02" pos="0 0 0" rgba="0 0 0 1" />
                        </body>
                    </body>
                </body>
            </body>
            <body name="FL_hip" pos="0.0946 0.062 -0.071">
                <inertial pos="0.049109 0.0014996 -1.9828E-05" quat="0.5 0.5 0.5 0.5" mass="0.62455" diaginertia="0.00080416 0.00051175 0.00043104" />
                <joint name="FL_hip_joint" pos="0 0 0" axis="1 0 0" limited="true" range="-0.48 0.48" />
                <geom type="mesh" contype="0" conaffinity="0" group="1" rgba="1 1 1 1" mesh="FL_hip" />
                <geom size="0.046 0.02" pos="0 0.03 0" quat="0.707107 0.707107 0 0" type="cylinder" rgba="1 1 1 0" />

                <body name="FL_thigh" pos="0.085 0.03295 0">
                    <inertial pos="0.00040284 0.05094 -0.044849" quat="0.999 0 -0.038 0" mass="1.107" diaginertia="0.0030336 0.0026249 0.00046586" />
                    <joint name="FL_thigh_joint" pos="0 0 0" axis="0 1 0" limited="true" range="-1.44 1.44" />
                    <geom type="mesh" contype="0" conaffinity="0" group="1" rgba="1 1 1 1" mesh="FL_thigh" />
                    <geom size="0.11 0.012 0.017" pos="0 0 -0.11" quat="0.707107 0 0.707107 0" type="box" rgba="1 1 1 0" />
                    
                    <body name="FL_calf" pos="0 0.0705 -0.22">
                        <inertial pos="0.017331 -3.8626E-05 -0.100135" quat="0.762 0.01 0.018 0.647" mass="0.29248" diaginertia="0.0009493 0.0009033 0.00006306" />
                        <joint name="FL_calf_joint" pos="0 0 0" axis="0 1 0" limited="true" range="-2.7 -0.6" />
                        <geom type="mesh" contype="0" conaffinity="0" group="1" rgba="0 0 0 1" mesh="FL_calf" />
                        <geom size="0.1 0.008 0.008" pos="0 0 -0.1" quat="0.707107 0 0.707107 0" type="box" rgba="0 0 0 0" />
                        
                        <body name="FL_foot" pos="0.0015191 -0.00024999 -0.22467">
                            <inertial pos="0 0 0" mass="0.0335" diaginertia="5.36e-6 5.36e-6 5.36e-6"/>
                            <geom type="mesh" contype="0" conaffinity="0" group="1" rgba="0 0 0 1" mesh="FL_foot" />
                            <geom size="0.02" pos="0 0 0" rgba="0 0 0 1" />
                        </body>
                    </body>
                </body>
            </body>
            <body name="RR_hip" pos="-0.2146 -0.062 -0.071">
                <inertial pos="-0.050937 -0.001551 2.072E-05" quat="0.5 0.5 -0.5 0.5" mass="0.60377" diaginertia="0.00079963 0.00050292 0.00042651" />
                <joint name="RR_hip_joint" pos="0 0 0" axis="1 0 0" limited="true" range="-0.48 0.48" />
                <geom type="mesh" contype="0" conaffinity="0" group="1" rgba="1 1 1 1" mesh="RR_hip" />
                <geom size="0.046 0.02" pos="0 -0.03 0" quat="0.707107 0.707107 0 0" type="cylinder" rgba="1 1 1 0" />

                <body name="RR_thigh" pos="-0.085 -0.03295 0">
                    <inertial pos="1.288e-05 -0.05094 -0.04485" quat="0.999 0 -0.038 0" mass="1.107" diaginertia="0.0030336 0.0026254 0.00046537" />
                    <joint name="RR_thigh_joint" pos="0 0 0" axis="0 1 0" limited="true" range="-1.44 1.44" />
                    <geom type="mesh" contype="0" conaffinity="0" group="1" rgba="1 1 1 1" mesh="RR_thigh" />
                    <geom size="0.11 0.012 0.017" pos="0 0 -0.11" quat="0.707107 0 0.707107 0" type="box" rgba="1 1 1 0" />
                    
                    <body name="RR_calf" pos="0 -0.0705 -0.22">
                        <inertial pos="0.01731 3.8634E-05 -0.100139" quat="0.762 0.01 0.018 0.647" mass="0.29248" diaginertia="0.0009493 0.0009031 0.00006325" />
                        <joint name="RR_calf_joint" pos="0 0 0" axis="0 1 0" limited="true" range="-2.7 -0.6" />
                        <geom type="mesh" contype="0" conaffinity="0" group="1" rgba="0 0 0 1" mesh="RR_calf" />
                        <geom size="0.1 0.008 0.008" pos="0 0 -0.1" quat="0.707107 0 0.707107 0" type="box" rgba="0 0 0 0" />
                        
                        <body name="RR_foot" pos="0.0015191 0.00025002 -0.22467">
                            <inertial pos="0 0 0" mass="0.0335" diaginertia="5.36e-6 5.36e-6 5.36e-6"/>
                            <geom type="mesh" contype="0" conaffinity="0" group="1" rgba="0 0 0 1" mesh="RR_foot" />
                            <geom size="0.02" pos="0 0 0" rgba="0 0 0 1" />
                        </body>
                    </body>
                </body>
            </body>
            <body name="RL_hip" pos="-0.2146 0.062 -0.071">
                <inertial pos="-0.050937 0.001551 2.072E-05" quat="0.5 0.5 0.5 0.5" mass="0.60377" diaginertia="0.00079963 0.00050292 0.00042651" />
                <joint name="RL_hip_joint" pos="0 0 0" axis="1 0 0" limited="true" range="-0.48 0.48" />
                <geom type="mesh" contype="0" conaffinity="0" group="1" rgba="1 1 1 1" mesh="RL_hip" />
                <geom size="0.046 0.02" pos="0 0.03 0" quat="0.707107 0.707107 0 0" type="cylinder" rgba="1 1 1 0" />

                <body name="RL_thigh" pos="-0.085 0.03295 0">
                    <inertial pos="4.708e-05 0.05094 -0.04485" quat="0.999 0 -0.038 0" mass="1.107" diaginertia="0.0030336 0.0026254 0.00046537" />
                    <joint name="RL_thigh_joint" pos="0 0 0" axis="0 1 0" limited="true" range="-1.44 1.44" />
                    <geom type="mesh" contype="0" conaffinity="0" group="1" rgba="1 1 1 1" mesh="RL_thigh" />
                    <geom size="0.11 0.012 0.017" pos="0 0 -0.11" quat="0.707107 0 0.707107 0" type="box" rgba="1 1 1 0" />
                    
                    <body name="RL_calf" pos="0 0.0705 -0.22">
                        <inertial pos="0.01733 -3.8626E-05 -0.100135" quat="0.762 0.01 0.018 0.647" mass="0.29248" diaginertia="0.0009493 0.0009033 0.00006306" />
                        <joint name="RL_calf_joint" pos="0 0 0" axis="0 1 0" limited="true" range="-2.7 -0.6" />
                        <geom type="mesh" contype="0" conaffinity="0" group="1" rgba="0 0 0 1" mesh="RL_calf" />
                        <geom size="0.1 0.008 0.008" pos="0 0 -0.1" quat="0.707107 0 0.707107 0" type="box" rgba="0 0 0 0" />
                        
                        <body name="RL_foot" pos="0.0015191 -0.00024998 -0.22467">
                            <inertial pos="0 0 0" mass="0.0335" diaginertia="5.36e-6 5.36e-6 5.36e-6"/>
                            <geom type="mesh" contype="0" conaffinity="0" group="1" rgba="0 0 0 1" mesh="RL_foot" />
                            <geom size="0.02" pos="0 0 0" rgba="0 0 0 1" />
                        </body>
                    </body>
                </body>
            </body>
        </body>
    </worldbody>
    <actuator>       
        <motor name="FR_hip"       gear="1" joint="FR_hip_joint"/>
        <motor name="FR_thigh"     gear="1" joint="FR_thigh_joint"/>
        <motor name="FR_calf"      gear="1" joint="FR_calf_joint"/>
        <motor name="FL_hip"       gear="1" joint="FL_hip_joint"/>
        <motor name="FL_thigh"     gear="1" joint="FL_thigh_joint"/>
        <motor name="FL_calf"      gear="1" joint="FL_calf_joint"/>
        <motor name="RR_hip"       gear="1" joint="RR_hip_joint"/>
        <motor name="RR_thigh"     gear="1" joint="RR_thigh_joint"/>
        <motor name="RR_calf"      gear="1" joint="RR_calf_joint"/>
        <motor name="RL_hip"       gear="1" joint="RL_hip_joint"/>
        <motor name="RL_thigh"     gear="1" joint="RL_thigh_joint"/>
        <motor name="RL_calf"      gear="1" joint="RL_calf_joint"/>
    </actuator>

    <sensor>
        <jointpos name="FR_hip_pos"     joint="FR_hip_joint"/>
        <jointpos name="FR_thigh_pos"   joint="FR_thigh_joint"/>
        <jointpos name="FR_calf_pos"    joint="FR_calf_joint"/>
        <jointpos name="FL_hip_pos"     joint="FL_hip_joint"/>
        <jointpos name="FL_thigh_pos"   joint="FL_thigh_joint"/>
        <jointpos name="FL_calf_pos"    joint="FL_calf_joint"/>
        <jointpos name="RR_hip_pos"     joint="RR_hip_joint"/>
        <jointpos name="RR_thigh_pos"   joint="RR_thigh_joint"/>
        <jointpos name="RR_calf_pos"    joint="RR_calf_joint"/>
        <jointpos name="RL_hip_pos"     joint="RL_hip_joint"/>
        <jointpos name="RL_thigh_pos"   joint="RL_thigh_joint"/>
        <jointpos name="RL_calf_pos"    joint="RL_calf_joint"/>

        <jointvel name="FR_hip_vel"     joint="FR_hip_joint"/>
        <jointvel name="FR_thigh_vel"   joint="FR_thigh_joint"/>
        <jointvel name="FR_calf_vel"    joint="FR_calf_joint"/>
        <jointvel name="FL_hip_vel"     joint="FL_hip_joint"/>
        <jointvel name="FL_thigh_vel"   joint="FL_thigh_joint"/>
        <jointvel name="FL_calf_vel"    joint="FL_calf_joint"/>
        <jointvel name="RR_hip_vel"     joint="RR_hip_joint"/>
        <jointvel name="RR_thigh_vel"   joint="RR_thigh_joint"/>
        <jointvel name="RR_calf_vel"    joint="RR_calf_joint"/>
        <jointvel name="RL_hip_vel"     joint="RL_hip_joint"/>
        <jointvel name="RL_thigh_vel"   joint="RL_thigh_joint"/>
        <jointvel name="RL_calf_vel"    joint="RL_calf_joint"/>

        <accelerometer name="Body_Acc" site="imu"/>
        <gyro name="Body_Gyro" site="imu"/>
        <framepos name="Body_Pos" objtype="site" objname="imu"/>
        <framequat name="Body_Quat" objtype="site" objname="imu"/>
    </sensor>
</mujoco>