<?xml version="1.0" encoding="utf-8"?>
<!-- This URDF was automatically created by SolidWorks to URDF Exporter! Originally created by Stephen Brawner (brawner@gmail.com) 
     Commit Version: 1.6.0-4-g7f85cfe  Build Version: 1.6.7995.38578
     For more information, please see http://wiki.ros.org/sw_urdf_exporter -->
<robot
  name="mybot_v2_1">
  <link
    name="body">
    <inertial>
      <origin
        xyz="0 0 0"
        rpy="0 0 0" />
      <mass
        value="3.70357154" />
      <inertia
        ixx="0.02485973"
        ixy="7E-08"
        ixz="2.029E-05"
        iyy="0.06519119"
        iyz="1.2E-06"
        izz="0.07602832" />
    </inertial>
    <visual>
      <origin
        xyz="0 0 0"
        rpy="0 0 0" />
      <geometry>
        <mesh
          filename="../meshes/body.STL" />
      </geometry>
      <material
        name="">
        <color
          rgba="0.84706 0.84706 0.84706 1" />
      </material>
    </visual>
    <collision>
      <origin xyz="-0.00 0 -0.01" rpy="0 0 0" />
      <geometry>
        <box size="0.30 0.22 0.16" />
      </geometry>
    </collision>
  </link>

<joint name="imu_joint" type="fixed">
    <parent link="body"/>
    <child link="imu_link"/>
    <origin rpy="0 0 0" xyz="-0.0 0 -0.0"/> 
  </joint>
  
  <link name="imu_link">
    <inertial>
      <mass value="0.001"/>
      <origin rpy="0 0 0" xyz="0 0 0"/>
      <inertia ixx="0.0001" ixy="0" ixz="0" iyy="0.0001" iyz="0" izz="0.0001"/>
    </inertial>
    <visual>
      <origin rpy="0 0 0" xyz="0 0 0"/>
      <geometry>
        <box size="0.01 0.01 0.01"/>
      </geometry>
      <material name="red"/>
    </visual>
    </link>

  <link
    name="FL_hip">
    <inertial>
      <origin
        xyz="0.06912954 0.00308032 -3.864E-05"
        rpy="0 0 0" />
      <mass
        value="0.88715151" />
      <inertia
        ixx="0.00069961"
        ixy="-5.524E-05"
        ixz="1.61E-06"
        iyy="0.001851"
        iyz="-2.9E-07"
        izz="0.0015654" />
    </inertial>
    <visual>
      <origin
        xyz="0 0 0"
        rpy="0 0 0" />
      <geometry>
        <mesh
          filename="../meshes/FL_hip.STL" />
      </geometry>
      <material
        name="">
        <color
          rgba="1 1 1 1" />
      </material>
    </visual>
    <collision>
      <origin xyz="0.09 0 0" rpy="1.5707963 0 0" />
      <geometry>
        <cylinder length="0.05" radius="0.05" />
      </geometry>
    </collision>
  </link>
  <joint
    name="FL_hip_joint"
    type="revolute">
    <origin
      xyz="0.15106 0.062037 0.0087919"
      rpy="0 0 0" />
    <parent
      link="body" />
    <child
      link="FL_hip" />
    <axis
      xyz="1 0 0" />
    <dynamics damping="0.0" friction="0.1"/>
    <limit effort="33.5" lower="-0.8" upper="0.8" velocity="28"/>
  </joint>
  <link
    name="FL_thigh">
    <inertial>
      <origin
        xyz="-0.0017695 0.053064 -0.039958"
        rpy="0 0 0" />
      <mass
        value="1.58133941" />
      <inertia
        ixx="0.0086776"
        ixy="6.478E-05"
        ixz="-0.00018618"
        iyy="0.0083172"
        iyz="0.0014097"
        izz="0.0021556" />
    </inertial>
    <visual>
      <origin
        xyz="0 0 0"
        rpy="0 0 0" />
      <geometry>
        <mesh
          filename="../meshes/FL_thigh.STL" />
      </geometry>
      <material
        name="">
        <color
          rgba="1 1 1 1" />
      </material>
    </visual>
    <collision>
      <origin xyz="0 0.08 -0.1" rpy="0 0 0" />
      <geometry>
        <box size="0.04 0.04 0.2" />
      </geometry>
    </collision>
  </link>
  <joint
    name="FL_thigh_joint"
    type="revolute">
    <origin
      xyz="0.089 0.02895 0"
      rpy="0 0 0" />
    <parent
      link="FL_hip" />
    <child
      link="FL_thigh" />
    <axis
      xyz="0 1 0" />
    <dynamics damping="0.0" friction="0.1"/>
    <limit effort="33.5" lower="-1.04" upper="4.18" velocity="28"/>
  </joint>
  <link
    name="FL_calf">
    <inertial>
      <origin
        xyz="0.0023755 -2.9153E-05 -0.085563"
        rpy="0 0 0" />
      <mass
        value="0.34494" />
      <inertia
        ixx="0.00211121"
        ixy="3E-07"
        ixz="0.00039966"
        iyy="0.00219234"
        iyz="-1.92E-06"
        izz="0.00015881" />
    </inertial>
    <visual>
      <origin
        xyz="0 0 0"
        rpy="0 0 0" />
      <geometry>
        <mesh
          filename="../meshes/FL_calf.STL" />
      </geometry>
      <material
        name="">
        <color
          rgba="0.84706 0.84706 0.84706 1" />
      </material>
    </visual>
    <collision>
      <origin xyz="0 0 -0.1" rpy="0 -0.3 0" />
      <geometry>
        <box size="0.03 0.05 0.2" />
      </geometry>
    </collision>
  </link>
  <joint
    name="FL_calf_joint"
    type="revolute">
    <origin
      xyz="0 0.0753 -0.22"
      rpy="0 0 0" />
    <parent
      link="FL_thigh" />
    <child
      link="FL_calf" />
    <axis
      xyz="0 1 0" />
    <dynamics damping="0.0" friction="0.3"/>
    <limit effort="78.17" lower="-2.69" upper="-0.91" velocity="12.0"/>
  </joint>
  <link
    name="FL_foot">
    <inertial>
      <origin
        xyz="0 0 0"
        rpy="0 0 0" />
      <mass
        value="0.03351" />
      <inertia
        ixx="5.3617E-06"
        ixy="0"
        ixz="0"
        iyy="5.3617E-06"
        iyz="0"
        izz="5.3617E-06" />
    </inertial>
    <visual>
      <origin
        xyz="0 0 0"
        rpy="0 0 0" />
      <geometry>
        <mesh
          filename="../meshes/FL_foot.STL" />
      </geometry>
      <material
        name="">
        <color
          rgba="0.29804 0.29804 0.29804 1" />
      </material>
    </visual>
    <collision>
      <origin xyz="0 0 0" rpy="0 0 0" />
      <geometry>
        <sphere radius="0.02" />
      </geometry>
    </collision>
  </link>
  <joint
    name="FL_foot_joint"
    type="fixed">
    <origin
      xyz="0 -0.00025 -0.22336"
      rpy="0 0 0" />
    <parent
      link="FL_calf" />
    <child
      link="FL_foot" />
    <axis
      xyz="0 0 0" />
  </joint>
  <link
    name="FR_hip">
    <inertial>
      <origin
        xyz="0.06924677 -0.00308032 -3.847E-05"
        rpy="0 0 0" />
      <mass
        value="0.88715151" />
      <inertia
        ixx="0.00069961"
        ixy="5.408E-05"
        ixz="-2.6E-07"
        iyy="0.00185513"
        iyz="2.9E-07"
        izz="0.00156952" />
    </inertial>
    <visual>
      <origin
        xyz="0 0 0"
        rpy="0 0 0" />
      <geometry>
        <mesh
          filename="../meshes/FR_hip.STL" />
      </geometry>
      <material
        name="">
        <color
          rgba="1 1 1 1" />
      </material>
    </visual>
    <collision>
      <origin xyz="0.09 0 0" rpy="1.5707963 0 0" />
      <geometry>
        <cylinder length="0.05" radius="0.05" />
      </geometry>
    </collision>
  </link>
  <joint
    name="FR_hip_joint"
    type="revolute">
    <origin
      xyz="0.15106 -0.061963 0.0087919"
      rpy="0 0 0" />
    <parent
      link="body" />
    <child
      link="FR_hip" />
    <axis
      xyz="1 0 0" />
    <dynamics damping="0.0" friction="0.1"/>
    <limit effort="33.5" lower="-0.8" upper="0.8" velocity="28"/>
  </joint>
  <link
    name="FR_thigh">
    <inertial>
      <origin
        xyz="-0.00184722 -0.05308638 -0.03995616"
        rpy="0 0 0" />
      <mass
        value="1.5813" />
      <inertia
        ixx="0.00867822"
        ixy="-6.202E-05"
        ixz="-0.00018385"
        iyy="0.00831708"
        iyz="-0.00140961"
        izz="0.00215611" />
    </inertial>
    <visual>
      <origin
        xyz="0 0 0"
        rpy="0 0 0" />
      <geometry>
        <mesh
          filename="../meshes/FR_thigh.STL" />
      </geometry>
      <material
        name="">
        <color
          rgba="1 1 1 1" />
      </material>
    </visual>
    <collision>
      <origin xyz="0 -0.08 -0.1" rpy="0 0 0" />
      <geometry>
        <box size="0.04 0.04 0.2" />
      </geometry>
    </collision>
  </link>
  <joint
    name="FR_thigh_joint"
    type="revolute">
    <origin
      xyz="0.0889996956253649 -0.0289500000000027 0"
      rpy="0 0 0" />
    <parent
      link="FR_hip" />
    <child
      link="FR_thigh" />
    <axis
      xyz="0 1 0" />
    <dynamics damping="0.0" friction="0.1"/>
    <limit effort="33.5" lower="-1.04" upper="4.18" velocity="28"/>
  </joint>
  <link
    name="FR_calf">
    <inertial>
      <origin
        xyz="0.0023755 2.6551E-05 -0.085563"
        rpy="0 0 0" />
      <mass
        value="0.34494" />
      <inertia
        ixx="0.00211121"
        ixy="-2.8E-07"
        ixz="0.00039966"
        iyy="0.00219234"
        iyz="1.82E-06"
        izz="0.00015881" />
    </inertial>
    <visual>
      <origin
        xyz="0 0 0"
        rpy="0 0 0" />
      <geometry>
        <mesh
          filename="../meshes/FR_calf.STL" />
      </geometry>
      <material
        name="">
        <color
          rgba="0.84706 0.84706 0.84706 1" />
      </material>
    </visual>
    <collision>
      <origin xyz="0 0 -0.1" rpy="0 -0.3 0" />
      <geometry>
        <box size="0.03 0.05 0.2" />
      </geometry>
    </collision>
  </link>
  <joint
    name="FR_calf_joint"
    type="revolute">
    <origin
      xyz="0 -0.0752999999999987 -0.220000271728272"
      rpy="0 0 0" />
    <parent
      link="FR_thigh" />
    <child
      link="FR_calf" />
    <axis xyz="0 1 0" />
    <dynamics damping="0.0" friction="0.3"/>
    <limit effort="78.17" lower="-2.69" upper="-0.91" velocity="12.0"/>
  </joint>
  <link
    name="FR_foot">
    <inertial>
      <origin
        xyz="0 0 0"
        rpy="0 0 0" />
      <mass
        value="0.03351" />
      <inertia
        ixx="5.3617E-06"
        ixy="0"
        ixz="0"
        iyy="5.3617E-06"
        iyz="0"
        izz="5.3617E-06" />
    </inertial>
    <visual>
      <origin
        xyz="0 0 0"
        rpy="0 0 0" />
      <geometry>
        <mesh
          filename="../meshes/FR_foot.STL" />
      </geometry>
      <material
        name="">
        <color
          rgba="0.29804 0.29804 0.29804 1" />
      </material>
    </visual>
    <collision>
      <origin xyz="0 0 0" rpy="0 0 0" />
      <geometry>
        <sphere radius="0.02" />
      </geometry>
    </collision>
  </link>
  <joint
    name="FR_foot_joint"
    type="fixed">
    <origin
      xyz="0 0.00025000000001113 -0.223362537893242"
      rpy="0 0 0" />
    <parent
      link="FR_calf" />
    <child
      link="FR_foot" />
    <axis
      xyz="0 0 0" />
  </joint>
  <link
    name="RL_hip">
    <inertial>
      <origin
        xyz="-0.0691296 0.00308032 3.847E-05"
        rpy="0 0 0" />
      <mass
        value="0.88715151" />
      <inertia
        ixx="0.00069961"
        ixy="5.524E-05"
        ixz="1.61E-06"
        iyy="0.00185101"
        iyz="2.9E-07"
        izz="0.00156541" />
    </inertial>
    <visual>
      <origin
        xyz="0 0 0"
        rpy="0 0 0" />
      <geometry>
        <mesh
          filename="../meshes/RL_hip.STL" />
      </geometry>
      <material
        name="">
        <color
          rgba="1 1 1 1" />
      </material>
    </visual>
    <collision>
      <origin xyz="-0.09 0 0" rpy="1.5707963 0 0" />
      <geometry>
        <cylinder length="0.05" radius="0.05" />
      </geometry>
    </collision>
  </link>
  <joint
    name="RL_hip_joint"
    type="revolute">
    <origin
      xyz="-0.15014 0.062037 0.0087919"
      rpy="0 0 0" />
    <parent
      link="body" />
    <child
      link="RL_hip" />
    <axis xyz="1 0 0" />
    <dynamics damping="0.0" friction="0.1"/>
    <limit effort="33.5" lower="-0.8" upper="0.8" velocity="28"/>
  </joint>
  <link
    name="RL_thigh">
    <inertial>
      <origin
        xyz="-0.00271376 0.05342776 -0.03973152"
        rpy="0 0 0" />
      <mass
        value="1.593154" />
      <inertia
        ixx="0.00874288"
        ixy="9.667E-05"
        ixz="-0.00020428"
        iyy="0.00841103"
        iyz="0.00139054"
        izz="0.00223462" />
    </inertial>
    <visual>
      <origin
        xyz="0 0 0"
        rpy="0 0 0" />
      <geometry>
        <mesh
          filename="../meshes/RL_thigh.STL" />
      </geometry>
      <material
        name="">
        <color
          rgba="1 1 1 1" />
      </material>
    </visual>
    <collision>
      <origin xyz="0 0.08 -0.1" rpy="0 0 0" />
      <geometry>
        <box size="0.04 0.04 0.2" />
      </geometry>
    </collision>
  </link>
  <joint
    name="RL_thigh_joint"
    type="revolute">
    <origin
      xyz="-0.0889996956253644 0.028949999999991 0"
      rpy="0 0 0" />
    <parent
      link="RL_hip" />
    <child
      link="RL_thigh" />
    <axis xyz="0 1 0" />
    <dynamics damping="0.0" friction="0.1"/>
    <limit effort="33.5" lower="-1.04" upper="4.18" velocity="28"/>
  </joint>
  <link
    name="RL_calf">
    <inertial>
      <origin
        xyz="0.0023755 -4.7806E-05 -0.085563"
        rpy="0 0 0" />
      <mass
        value="0.34494" />
      <inertia
        ixx="0.00211121"
        ixy="2.2E-07"
        ixz="0.00039966"
        iyy="0.00219234"
        iyz="-1.23E-06"
        izz="0.00015881" />
    </inertial>
    <visual>
      <origin
        xyz="0 0 0"
        rpy="0 0 0" />
      <geometry>
        <mesh
          filename="../meshes/RL_calf.STL" />
      </geometry>
      <material
        name="">
        <color
          rgba="0.84706 0.84706 0.84706 1" />
      </material>
    </visual>
    <collision>
      <origin xyz="0 0 -0.1" rpy="0 -0.3 0" />
      <geometry>
        <box size="0.03 0.05 0.2" />
      </geometry>
    </collision>
  </link>
  <joint
    name="RL_calf_joint"
    type="revolute">
    <origin
      xyz="0 0.075299999999997 -0.220000271728261"
      rpy="0 0 0" />
    <parent
      link="RL_thigh" />
    <child
      link="RL_calf" />
    <axis xyz="0 1 0" />
    <dynamics damping="0.0" friction="0.3"/>
    <limit effort="78.17" lower="-2.69" upper="-0.91" velocity="12.0"/>
  </joint>
  <link
    name="RL_foot">
    <inertial>
      <origin
        xyz="0 0 0"
        rpy="0 0 0" />
      <mass
        value="0.03351" />
      <inertia
        ixx="5.3617E-06"
        ixy="0"
        ixz="0"
        iyy="5.3617E-06"
        iyz="0"
        izz="5.3617E-06" />
    </inertial>
    <visual>
      <origin
        xyz="0 0 0"
        rpy="0 0 0" />
      <geometry>
        <mesh
          filename="../meshes/RL_foot.STL" />
      </geometry>
      <material
        name="">
        <color
          rgba="0.29804 0.29804 0.29804 1" />
      </material>
    </visual>
    <collision>
      <origin xyz="0 0 0" rpy="0 0 0" />
      <geometry>
        <sphere radius="0.02" />
      </geometry>
    </collision>
  </link>
  <joint
    name="RL_foot_joint"
    type="fixed">
    <origin
      xyz="0 -0.000250000000010231 -0.223362537894357"
      rpy="0 0 0" />
    <parent
      link="RL_calf" />
    <child
      link="RL_foot" />
    <axis
      xyz="0 0 0" />
  </joint>
  <link
    name="RR_hip">
    <inertial>
      <origin
        xyz="-0.06924676 -0.00308032 3.847E-05"
        rpy="0 0 0" />
      <mass
        value="0.88715151" />
      <inertia
        ixx="0.00069961"
        ixy="-5.408E-05"
        ixz="-2.6E-07"
        iyy="0.00185513"
        iyz="-2.9E-07"
        izz="0.00156952" />
    </inertial>
    <visual>
      <origin
        xyz="0 0 0"
        rpy="0 0 0" />
      <geometry>
        <mesh
          filename="../meshes/RR_hip.STL" />
      </geometry>
      <material
        name="">
        <color
          rgba="1 1 1 1" />
      </material>
    </visual>
    <collision>
      <origin xyz="-0.09 0 0" rpy="1.5707963 0 0" />
      <geometry>
        <cylinder length="0.05" radius="0.05" />
      </geometry>
    </collision>
  </link>
  <joint
    name="RR_hip_joint"
    type="revolute">
    <origin
      xyz="-0.15013508 -0.0619632146458127 0.00879191128020729"
      rpy="0 0 0" />
    <parent
      link="body" />
    <child
      link="RR_hip" />
    <axis xyz="1 0 0" />
    <dynamics damping="0.0" friction="0.1"/>
    <limit effort="33.5" lower="-0.8" upper="0.8" velocity="28"/>
  </joint>
  <link
    name="RR_thigh">
    <inertial>
      <origin
        xyz="-0.00297935 -0.05327553 -0.03814011"
        rpy="0 0 0" />
      <mass
        value="1.58306405" />
      <inertia
        ixx="0.00816821"
        ixy="-0.00010062"
        ixz="-0.00025438"
        iyy="0.00785378"
        iyz="-0.00133132"
        izz="0.00221841" />
    </inertial>
    <visual>
      <origin
        xyz="0 0 0"
        rpy="0 0 0" />
      <geometry>
        <mesh
          filename="../meshes/RR_thigh.STL" />
      </geometry>
      <material
        name="">
        <color
          rgba="1 1 1 1" />
      </material>
    </visual>
    <collision>
      <origin xyz="0 -0.08 -0.1" rpy="0 0 0" />
      <geometry>
        <box size="0.04 0.04 0.2" />
      </geometry>
    </collision>
  </link>
  <joint
    name="RR_thigh_joint"
    type="revolute">
    <origin
      xyz="-0.088999695625364 -0.0289499999999917 0"
      rpy="0 0 0" />
    <parent
      link="RR_hip" />
    <child
      link="RR_thigh" />
    <axis xyz="0 1 0" />
    <dynamics damping="0.0" friction="0.1"/>
    <limit effort="33.5" lower="-1.04" upper="4.18" velocity="28"/>
  </joint>

  <link
    name="RR_calf">
    <inertial>
      <origin
        xyz="0.0031074 -3.1371E-05 -0.084827"
        rpy="0 0 0" />
      <mass
        value="0.35539" />
      <inertia
        ixx="0.00207591"
        ixy="-3E-07"
        ixz="0.0003696"
        iyy="0.00214155"
        iyz="3.47E-06"
        izz="0.00016557" />
    </inertial>
    <visual>
      <origin
        xyz="0 0 0"
        rpy="0 0 0" />
      <geometry>
        <mesh
          filename="../meshes/RR_calf.STL" />
      </geometry>
      <material
        name="">
        <color
          rgba="0.84706 0.84706 0.84706 1" />
      </material>
    </visual>
    <collision>
      <origin xyz="0 0 -0.1" rpy="0 -0.3 0" />
      <geometry>
        <box size="0.03 0.05 0.2" />
      </geometry>
    </collision>
  </link>
  <joint
    name="RR_calf_joint"
    type="revolute">
    <origin
      xyz="0 -0.075299999999999 -0.220000271728268"
      rpy="0 0 0" />
    <parent
      link="RR_thigh" />
    <child
      link="RR_calf" />
    <axis xyz="0 1 0" />
    <dynamics damping="0.0" friction="0.3"/>
    <limit effort="78.17" lower="-2.69" upper="-0.91" velocity="12.0"/>
  </joint>
  <link
    name="RR_foot">
    <inertial>
      <origin
        xyz="0 0 0"
        rpy="0 0 0" />
      <mass
        value="0.03351" />
      <inertia
        ixx="5.3617E-06"
        ixy="0"
        ixz="0"
        iyy="5.3617E-06"
        iyz="0"
        izz="5.3617E-06" />
    </inertial>
    <visual>
      <origin
        xyz="0 0 0"
        rpy="0 0 0" />
      <geometry>
        <mesh
          filename="../meshes/RR_foot.STL" />
      </geometry>
      <material
        name="">
        <color
          rgba="0.29804 0.29804 0.29804 1" />
      </material>
    </visual>
    <collision>
      <origin xyz="0 0 0" rpy="0 0 0" />
      <geometry>
        <sphere radius="0.02" />
      </geometry>
    </collision>
  </link>
  <joint
    name="RR_foot_joint"
    type="fixed">
    <origin
      xyz="0 0.000250000000008521 -0.223362537894357"
      rpy="0 0 0" />
    <parent
      link="RR_calf" />
    <child
      link="RR_foot" />
    <axis
      xyz="0 0 0" />
  </joint>
</robot>